<?xml version="1.0" encoding="utf-8"?>
<!-- This URDF was automatically created by SolidWorks to URDF Exporter! Originally created by Stephen Brawner (brawner@gmail.com) 
     Commit Version: 1.5.1-0-g916b5db  Build Version: 1.5.7152.31018
     For more information, please see http://wiki.ros.org/sw_urdf_exporter -->
<robot
  name="floating_body_robot">
  <link
    name="floating_body">
    <inertial>
      <origin
        xyz="0.162269896425097 -0.913550914913996 0.492788959673433"
        rpy="0 0 0" />
      <mass
        value="110.615392516506" />
      <inertia
        ixx="4.86007264327987"
        ixy="-0.00202732296957763"
        ixz="-0.290738055135692"
        iyy="11.3366983871735"
        iyz="-0.0242427696641162"
        izz="14.0183001434337" />
    </inertial>
    <visual>
      <origin
        xyz="0 0 0"
        rpy="0 0 0" />
      <geometry>
        <mesh
          filename="package://floating_body_robot/meshes/floating_body.STL" />
      </geometry>
      <material
        name="">
        <color
          rgba="0.792156862745098 0.819607843137255 0.933333333333333 1" />
      </material>
    </visual>
    <collision>
      <origin
        xyz="0 0 0"
        rpy="0 0 0" />
      <geometry>
        <mesh
          filename="package://floating_body_robot/meshes/floating_body.STL" />
      </geometry>
    </collision>
  </link>
  <link
    name="right_back_ud">
    <inertial>
      <origin
        xyz="-0.01559909123975 -0.265026485547763 0.0925002736177307"
        rpy="0 0 0" />
      <mass
        value="110.615392516506" />
      <inertia
        ixx="14.0183001434337"
        ixy="0.119094731721884"
        ixz="-0.266332073662125"
        iyy="10.6260863599125"
        iyz="2.02420424029519"
        izz="5.57068467054079" />
    </inertial>
    <visual>
      <origin
        xyz="0 0 0"
        rpy="0 0 0" />
      <geometry>
        <mesh
          filename="package://floating_body_robot/meshes/right_back_ud.STL" />
      </geometry>
      <material
        name="">
        <color
          rgba="0.270588235294118 0.270588235294118 0.270588235294118 1" />
      </material>
    </visual>
    <collision>
      <origin
        xyz="0 0 0"
        rpy="0 0 0" />
      <geometry>
        <mesh
          filename="package://floating_body_robot/meshes/right_back_ud.STL" />
      </geometry>
    </collision>
  </link>
  <joint
    name="right_back_ud_joint"
    type="continuous">
    <origin
      xyz="-0.0127269631104085 -1.13303084067912 0.508388050913183"
      rpy="0.337303836546883 -1.5707963267949 0" />
    <parent
      link="floating_body" />
    <child
      link="right_back_ud" />
    <axis
      xyz="1 0 0" />
  </joint>
  <link
    name="left_back_ud">
    <inertial>
      <origin
        xyz="-0.01559909123975 -0.167043665708292 0.226631246248178"
        rpy="0 0 0" />
      <mass
        value="110.615392516506" />
      <inertia
        ixx="14.0183001434337"
        ixy="0.291421459173344"
        ixz="0.0137790318364976"
        iyy="4.86829110320707"
        iyz="0.230574187832195"
        izz="11.3284799272463" />
    </inertial>
    <visual>
      <origin
        xyz="0 0 0"
        rpy="0 0 0" />
      <geometry>
        <mesh
          filename="package://floating_body_robot/meshes/left_back_ud.STL" />
      </geometry>
      <material
        name="">
        <color
          rgba="0.270588235294118 0.270588235294118 0.270588235294118 1" />
      </material>
    </visual>
    <collision>
      <origin
        xyz="0 0 0"
        rpy="0 0 0" />
      <geometry>
        <mesh
          filename="package://floating_body_robot/meshes/left_back_ud.STL" />
      </geometry>
    </collision>
  </link>
  <joint
    name="left_back_ud_joint"
    type="continuous">
    <origin
      xyz="-0.0128101832847083 -0.693069002462942 0.508388050913183"
      rpy="1.53485218788834 -1.5707963267949 0" />
    <parent
      link="floating_body" />
    <child
      link="left_back_ud" />
    <axis
      xyz="1 0 0" />
  </joint>
  <link
    name="left_front_ud">
    <inertial>
      <origin
        xyz="-0.0155990912397497 0.23257807772421 0.212309492514357"
        rpy="0 0 0" />
      <mass
        value="110.615392516506" />
      <inertia
        ixx="14.0183001434337"
        ixy="0.291421459173344"
        ixz="0.0137790318364976"
        iyy="4.86829110320707"
        iyz="0.230574187832195"
        izz="11.3284799272463" />
    </inertial>
    <visual>
      <origin
        xyz="0 0 0"
        rpy="0 0 0" />
      <geometry>
        <mesh
          filename="package://floating_body_robot/meshes/left_front_ud.STL" />
      </geometry>
      <material
        name="">
        <color
          rgba="0.270588235294118 0.270588235294118 0.270588235294118 1" />
      </material>
    </visual>
    <collision>
      <origin
        xyz="0 0 0"
        rpy="0 0 0" />
      <geometry>
        <mesh
          filename="package://floating_body_robot/meshes/left_front_ud.STL" />
      </geometry>
    </collision>
  </link>
  <joint
    name="left_front_ud_joint"
    type="continuous">
    <origin
      xyz="0.38706810833078 -0.693020538834871 0.508388050913183"
      rpy="1.53485218788834 -1.5707963267949 0" />
    <parent
      link="floating_body" />
    <child
      link="left_front_ud" />
    <axis
      xyz="1 0 0" />
  </joint>
  <link
    name="right_front_ud">
    <inertial>
      <origin
        xyz="-0.0155990912397503 -0.0945601198979059 0.299687393052061"
        rpy="0 0 0" />
      <mass
        value="110.615392516506" />
      <inertia
        ixx="14.0183001434337"
        ixy="-0.267748546441764"
        ixz="0.115875124437449"
        iyy="6.30165945493594"
        iyz="2.69415104085255"
        izz="9.89511157551739" />
    </inertial>
    <visual>
      <origin
        xyz="0 0 0"
        rpy="0 0 0" />
      <geometry>
        <mesh
          filename="package://floating_body_robot/meshes/right_front_ud.STL" />
      </geometry>
      <material
        name="">
        <color
          rgba="0.270588235294118 0.270588235294118 0.270588235294118 1" />
      </material>
    </visual>
    <collision>
      <origin
        xyz="0 0 0"
        rpy="0 0 0" />
      <geometry>
        <mesh
          filename="package://floating_body_robot/meshes/right_front_ud.STL" />
      </geometry>
    </collision>
  </link>
  <joint
    name="right_front_ud_joint"
    type="continuous">
    <origin
      xyz="0.387102116229031 -1.13310642672703 0.508388050913183"
      rpy="2.06242586922736 -1.5707963267949 0" />
    <parent
      link="floating_body" />
    <child
      link="right_front_ud" />
    <axis
      xyz="1 0 0" />
  </joint>
  <link
    name="left_front_fb">
    <inertial>
      <origin
        xyz="-0.279310191213277 -0.437453968879025 -0.0390370556397751"
        rpy="0 0 0" />
      <mass
        value="110.615392516506" />
      <inertia
        ixx="6.4809847924466"
        ixy="-2.75444315758052"
        ixz="-0.584098919386964"
        iyy="9.82208276294297"
        iyz="-0.688273395274284"
        izz="13.9120036184975" />
    </inertial>
    <visual>
      <origin
        xyz="0 0 0"
        rpy="0 0 0" />
      <geometry>
        <mesh
          filename="package://floating_body_robot/meshes/left_front_fb.STL" />
      </geometry>
      <material
        name="">
        <color
          rgba="1 1 1 1" />
      </material>
    </visual>
    <collision>
      <origin
        xyz="0 0 0"
        rpy="0 0 0" />
      <geometry>
        <mesh
          filename="package://floating_body_robot/meshes/left_front_fb.STL" />
      </geometry>
    </collision>
  </link>
  <joint
    name="left_front_fb_joint"
    type="continuous">
    <origin
      xyz="0.623623267145709 -0.673083819009289 0.477534693761356"
      rpy="-0.12374073057921 0 -0.5235987755983" />
    <parent
      link="floating_body" />
    <child
      link="left_front_fb" />
    <axis
      xyz="1 0 0" />
  </joint>
  <link
    name="right_front_fb">
    <inertial>
      <origin
        xyz="-0.316245604883395 0.32331080609348 -0.295895931520665"
        rpy="0 0 0" />
      <mass
        value="110.615392516506" />
      <inertia
        ixx="6.47747336605989"
        ixy="1.81610509056504"
        ixz="-2.15191260626279"
        iyy="11.952601035355"
        iyz="2.15146501631304"
        izz="11.7849967724721" />
    </inertial>
    <visual>
      <origin
        xyz="0 0 0"
        rpy="0 0 0" />
      <geometry>
        <mesh
          filename="package://floating_body_robot/meshes/right_front_fb.STL" />
      </geometry>
      <material
        name="">
        <color
          rgba="1 1 1 1" />
      </material>
    </visual>
    <collision>
      <origin
        xyz="0 0 0"
        rpy="0 0 0" />
      <geometry>
        <mesh
          filename="package://floating_body_robot/meshes/right_front_fb.STL" />
      </geometry>
    </collision>
  </link>
  <joint
    name="right_front_fb_joint"
    type="continuous">
    <origin
      xyz="0.655150954525234 -1.13475473986496 0.477534693761359"
      rpy="0.775965204396531 0 0.52359877559829" />
    <parent
      link="floating_body" />
    <child
      link="right_front_fb" />
    <axis
      xyz="1 0 0" />
  </joint>
  <link
    name="left_back_fb">
    <inertial>
      <origin
        xyz="-0.283689111324848 0.272526656003463 0.31219355427269"
        rpy="0 0 0" />
      <mass
        value="110.615392516506" />
      <inertia
        ixx="6.47747336605995"
        ixy="1.72781994729062"
        ixz="2.22342164123537"
        iyy="12.1257646937801"
        iyz="-2.13770743940592"
        izz="11.611833114047" />
    </inertial>
    <visual>
      <origin
        xyz="0 0 0"
        rpy="0 0 0" />
      <geometry>
        <mesh
          filename="package://floating_body_robot/meshes/left_back_fb.STL" />
      </geometry>
      <material
        name="">
        <color
          rgba="1 1 1 1" />
      </material>
    </visual>
    <collision>
      <origin
        xyz="0 0 0"
        rpy="0 0 0" />
      <geometry>
        <mesh
          filename="package://floating_body_robot/meshes/left_back_fb.STL" />
      </geometry>
    </collision>
  </link>
  <joint
    name="left_back_fb_joint"
    type="continuous">
    <origin
      xyz="-0.290476624400439 -0.696749160543825 0.477534693761357"
      rpy="-0.816315568271687 0 -2.61799387799149" />
    <parent
      link="floating_body" />
    <child
      link="left_back_fb" />
    <axis
      xyz="1 0 0" />
  </joint>
  <link
    name="right_back_fb">
    <inertial>
      <origin
        xyz="-0.367866763739677 -0.407624510204562 0.0694105643533898"
        rpy="0 0 0" />
      <mass
        value="110.615392516506" />
      <inertia
        ixx="6.48098479244656"
        ixy="-2.74966865128766"
        ixz="0.606177337168678"
        iyy="9.83338882324928"
        iyz="0.720994682007765"
        izz="13.9006975581912" />
    </inertial>
    <visual>
      <origin
        xyz="0 0 0"
        rpy="0 0 0" />
      <geometry>
        <mesh
          filename="package://floating_body_robot/meshes/right_back_fb.STL" />
      </geometry>
      <material
        name="">
        <color
          rgba="1 1 1 1" />
      </material>
    </visual>
    <collision>
      <origin
        xyz="0 0 0"
        rpy="0 0 0" />
      <geometry>
        <mesh
          filename="package://floating_body_robot/meshes/right_back_fb.STL" />
      </geometry>
    </collision>
  </link>
  <joint
    name="right_back_fb_joint"
    type="continuous">
    <origin
      xyz="-0.36291729066453 -1.08746827895806 0.477534693761358"
      rpy="0.13176320546132 0 2.6179938779915" />
    <parent
      link="floating_body" />
    <child
      link="right_back_fb" />
    <axis
      xyz="1 0 0" />
  </joint>
</robot>